2018-05-23 20:13:06,729 INFO: MicroBlog startup [in /Users/m0k00eu/python-projects/dictionary/app/dictionary.py:17]
2018-05-23 20:28:54,431 ERROR: Exception on /index [GET] [in /Users/m0k00eu/python-projects/dictionary/venv/lib/python3.6/site-packages/flask/app.py:1761]
Traceback (most recent call last):
  File "/Users/m0k00eu/python-projects/dictionary/venv/lib/python3.6/site-packages/flask/app.py", line 2292, in wsgi_app
    response = self.full_dispatch_request()
  File "/Users/m0k00eu/python-projects/dictionary/venv/lib/python3.6/site-packages/flask/app.py", line 1815, in full_dispatch_request
    rv = self.handle_user_exception(e)
  File "/Users/m0k00eu/python-projects/dictionary/venv/lib/python3.6/site-packages/flask/app.py", line 1718, in handle_user_exception
    reraise(exc_type, exc_value, tb)
  File "/Users/m0k00eu/python-projects/dictionary/venv/lib/python3.6/site-packages/flask/_compat.py", line 35, in reraise
    raise value
  File "/Users/m0k00eu/python-projects/dictionary/venv/lib/python3.6/site-packages/flask/app.py", line 1813, in full_dispatch_request
    rv = self.dispatch_request()
  File "/Users/m0k00eu/python-projects/dictionary/venv/lib/python3.6/site-packages/flask/app.py", line 1799, in dispatch_request
    return self.view_functions[rule.endpoint](**req.view_args)
  File "/Users/m0k00eu/python-projects/dictionary/venv/lib/python3.6/site-packages/flask_login/utils.py", line 261, in decorated_view
    return func(*args, **kwargs)
  File "/Users/m0k00eu/python-projects/dictionary/app/home/routes.py", line 39, in searchWord
    app.logger.info("got query for "+queryWord);
NameError: name 'app' is not defined
2018-05-23 20:29:06,772 ERROR: Exception on /index [GET] [in /Users/m0k00eu/python-projects/dictionary/venv/lib/python3.6/site-packages/flask/app.py:1761]
Traceback (most recent call last):
  File "/Users/m0k00eu/python-projects/dictionary/venv/lib/python3.6/site-packages/flask/app.py", line 2292, in wsgi_app
    response = self.full_dispatch_request()
  File "/Users/m0k00eu/python-projects/dictionary/venv/lib/python3.6/site-packages/flask/app.py", line 1815, in full_dispatch_request
    rv = self.handle_user_exception(e)
  File "/Users/m0k00eu/python-projects/dictionary/venv/lib/python3.6/site-packages/flask/app.py", line 1718, in handle_user_exception
    reraise(exc_type, exc_value, tb)
  File "/Users/m0k00eu/python-projects/dictionary/venv/lib/python3.6/site-packages/flask/_compat.py", line 35, in reraise
    raise value
  File "/Users/m0k00eu/python-projects/dictionary/venv/lib/python3.6/site-packages/flask/app.py", line 1813, in full_dispatch_request
    rv = self.dispatch_request()
  File "/Users/m0k00eu/python-projects/dictionary/venv/lib/python3.6/site-packages/flask/app.py", line 1799, in dispatch_request
    return self.view_functions[rule.endpoint](**req.view_args)
  File "/Users/m0k00eu/python-projects/dictionary/venv/lib/python3.6/site-packages/flask_login/utils.py", line 261, in decorated_view
    return func(*args, **kwargs)
  File "/Users/m0k00eu/python-projects/dictionary/app/home/routes.py", line 39, in searchWord
    app.logger.info("got query for "+queryWord);
NameError: name 'app' is not defined
2018-05-23 20:29:08,311 ERROR: Exception on /index [GET] [in /Users/m0k00eu/python-projects/dictionary/venv/lib/python3.6/site-packages/flask/app.py:1761]
Traceback (most recent call last):
  File "/Users/m0k00eu/python-projects/dictionary/venv/lib/python3.6/site-packages/flask/app.py", line 2292, in wsgi_app
    response = self.full_dispatch_request()
  File "/Users/m0k00eu/python-projects/dictionary/venv/lib/python3.6/site-packages/flask/app.py", line 1815, in full_dispatch_request
    rv = self.handle_user_exception(e)
  File "/Users/m0k00eu/python-projects/dictionary/venv/lib/python3.6/site-packages/flask/app.py", line 1718, in handle_user_exception
    reraise(exc_type, exc_value, tb)
  File "/Users/m0k00eu/python-projects/dictionary/venv/lib/python3.6/site-packages/flask/_compat.py", line 35, in reraise
    raise value
  File "/Users/m0k00eu/python-projects/dictionary/venv/lib/python3.6/site-packages/flask/app.py", line 1813, in full_dispatch_request
    rv = self.dispatch_request()
  File "/Users/m0k00eu/python-projects/dictionary/venv/lib/python3.6/site-packages/flask/app.py", line 1799, in dispatch_request
    return self.view_functions[rule.endpoint](**req.view_args)
  File "/Users/m0k00eu/python-projects/dictionary/venv/lib/python3.6/site-packages/flask_login/utils.py", line 261, in decorated_view
    return func(*args, **kwargs)
  File "/Users/m0k00eu/python-projects/dictionary/app/home/routes.py", line 39, in searchWord
    app.logger.info("got query for "+queryWord);
NameError: name 'app' is not defined
2018-05-23 20:31:43,990 INFO: MicroBlog startup [in /Users/m0k00eu/python-projects/dictionary/app/dictionary.py:17]
2018-05-23 20:31:47,494 ERROR: Exception on /index [GET] [in /Users/m0k00eu/python-projects/dictionary/venv/lib/python3.6/site-packages/flask/app.py:1761]
Traceback (most recent call last):
  File "/Users/m0k00eu/python-projects/dictionary/venv/lib/python3.6/site-packages/flask/app.py", line 2292, in wsgi_app
    response = self.full_dispatch_request()
  File "/Users/m0k00eu/python-projects/dictionary/venv/lib/python3.6/site-packages/flask/app.py", line 1815, in full_dispatch_request
    rv = self.handle_user_exception(e)
  File "/Users/m0k00eu/python-projects/dictionary/venv/lib/python3.6/site-packages/flask/app.py", line 1718, in handle_user_exception
    reraise(exc_type, exc_value, tb)
  File "/Users/m0k00eu/python-projects/dictionary/venv/lib/python3.6/site-packages/flask/_compat.py", line 35, in reraise
    raise value
  File "/Users/m0k00eu/python-projects/dictionary/venv/lib/python3.6/site-packages/flask/app.py", line 1813, in full_dispatch_request
    rv = self.dispatch_request()
  File "/Users/m0k00eu/python-projects/dictionary/venv/lib/python3.6/site-packages/flask/app.py", line 1799, in dispatch_request
    return self.view_functions[rule.endpoint](**req.view_args)
  File "/Users/m0k00eu/python-projects/dictionary/venv/lib/python3.6/site-packages/flask_login/utils.py", line 261, in decorated_view
    return func(*args, **kwargs)
  File "/Users/m0k00eu/python-projects/dictionary/app/home/routes.py", line 39, in searchWord
    app.logger.info("got query for "+queryWord);
NameError: name 'app' is not defined
2018-05-23 20:31:48,440 ERROR: Exception on /index [GET] [in /Users/m0k00eu/python-projects/dictionary/venv/lib/python3.6/site-packages/flask/app.py:1761]
Traceback (most recent call last):
  File "/Users/m0k00eu/python-projects/dictionary/venv/lib/python3.6/site-packages/flask/app.py", line 2292, in wsgi_app
    response = self.full_dispatch_request()
  File "/Users/m0k00eu/python-projects/dictionary/venv/lib/python3.6/site-packages/flask/app.py", line 1815, in full_dispatch_request
    rv = self.handle_user_exception(e)
  File "/Users/m0k00eu/python-projects/dictionary/venv/lib/python3.6/site-packages/flask/app.py", line 1718, in handle_user_exception
    reraise(exc_type, exc_value, tb)
  File "/Users/m0k00eu/python-projects/dictionary/venv/lib/python3.6/site-packages/flask/_compat.py", line 35, in reraise
    raise value
  File "/Users/m0k00eu/python-projects/dictionary/venv/lib/python3.6/site-packages/flask/app.py", line 1813, in full_dispatch_request
    rv = self.dispatch_request()
  File "/Users/m0k00eu/python-projects/dictionary/venv/lib/python3.6/site-packages/flask/app.py", line 1799, in dispatch_request
    return self.view_functions[rule.endpoint](**req.view_args)
  File "/Users/m0k00eu/python-projects/dictionary/venv/lib/python3.6/site-packages/flask_login/utils.py", line 261, in decorated_view
    return func(*args, **kwargs)
  File "/Users/m0k00eu/python-projects/dictionary/app/home/routes.py", line 39, in searchWord
    app.logger.info("got query for "+queryWord);
NameError: name 'app' is not defined
2018-05-23 20:31:49,560 ERROR: Exception on /index [GET] [in /Users/m0k00eu/python-projects/dictionary/venv/lib/python3.6/site-packages/flask/app.py:1761]
Traceback (most recent call last):
  File "/Users/m0k00eu/python-projects/dictionary/venv/lib/python3.6/site-packages/flask/app.py", line 2292, in wsgi_app
    response = self.full_dispatch_request()
  File "/Users/m0k00eu/python-projects/dictionary/venv/lib/python3.6/site-packages/flask/app.py", line 1815, in full_dispatch_request
    rv = self.handle_user_exception(e)
  File "/Users/m0k00eu/python-projects/dictionary/venv/lib/python3.6/site-packages/flask/app.py", line 1718, in handle_user_exception
    reraise(exc_type, exc_value, tb)
  File "/Users/m0k00eu/python-projects/dictionary/venv/lib/python3.6/site-packages/flask/_compat.py", line 35, in reraise
    raise value
  File "/Users/m0k00eu/python-projects/dictionary/venv/lib/python3.6/site-packages/flask/app.py", line 1813, in full_dispatch_request
    rv = self.dispatch_request()
  File "/Users/m0k00eu/python-projects/dictionary/venv/lib/python3.6/site-packages/flask/app.py", line 1799, in dispatch_request
    return self.view_functions[rule.endpoint](**req.view_args)
  File "/Users/m0k00eu/python-projects/dictionary/venv/lib/python3.6/site-packages/flask_login/utils.py", line 261, in decorated_view
    return func(*args, **kwargs)
  File "/Users/m0k00eu/python-projects/dictionary/app/home/routes.py", line 39, in searchWord
    app.logger.info("got query for "+queryWord);
NameError: name 'app' is not defined
2018-05-26 10:00:26,819 INFO: MicroBlog startup [in /Users/m0k00eu/python-projects/dictionary/app/dictionary.py:18]
